Workbook

Sheet Properties
B2: Volume | C2: 78
B3: Issue | C3: 6
B4: Article Title | C4: Rethinking the Administrative Remand Rule
B5: Author | C5: Smith
B6: SE | C6: Mariah Uustal
B7: Drive Folder ID | C7: 1QraZedvhM1pqTguKecOlRKZ62GUwcgnd
B8: Drive Sourcepull ID | C8: 1VmyDEdY-rZ9IfPP9oyBpoZpjcDWGggJR
B9: Drive R1 ID | C9: 1OkcpifbUiC1Y6G2u5ApzxEwKzOL1_kpP
B10: Drive R2 ID | C10: 1ECxOEr3giAvViqLOOB3XM6YZlFhRIkcx
B11: Primary ME | C11: Managing Editor
B12: MEMs | C12: Lucia Jiang
C13: Steve Sangbeom Heo
C14: Isabel Gallegos
C15: Ben Rosenthal
C16: Lucia Zheng
C17: Jinna Lee
C18: Breeze Velazquez
C19: Marcus Ellinas

Sheet Raw Output
A1: 1 | B1: Cite# | C1: Footnote Text | D1: Citation Text | E1: Source Name | F1: Warnings | G1: 1
A2: 1 | B2: 1 | C2: Pewećeli is a character in the Washoe Tribe’s creation story, and Pewećeli Yeweš means “Pewećeli’s trail” or “path” in reference to a trade route heading west. Email correspondence with Herman Miller, Culture/Language Resources Director, Washoe Tribe of Nevada and California (Oct. 16, 2024) (on file with the author); see also Claire Cudahy, “Washoe youth follow ancestors’ footsteps in Hope Valley,” Tahoe Daily Tribune (Jan. 25, 2018), https://www.tahoedailytribune.com/news/local/washoe-youth-follow-ancestors-footsteps-in-hope-valley-video/; U.S. Forest Service, Carson Ranger District, East Carson River Strategy, 4-5 (July 2007), http://www.theanglersedge.com/downloads/East_Carson_River_Strategy_061907.pdf. For a history of the Washoe and the lands they inhabited, see The Washoe Tribe of Nevada and California, WA SHE SHU: “The Washoe People” Past and Present (2009), https://www.fs.usda.gov/Internet/FSE_DOCUMENTS/stelprdb5251066.pdf; Washoe Tribe of California and Nevada, Washoe History: A Brief Summary (2020), https://washoetribe.us/aboutpage/4-Page-washoe-history. Frank Tortorich, Jr., The Opening of the Carson River Route, 18 Overland Journal 1, 22 (Spring 2000); Jeff Munson, “Emigrant Trail tour promises spectacular colors,” Tahoe Daily Tribune (Oct. 12, 2005), https://www.tahoedailytribune.com/news/emigrant-trail-tour-promises-spectacular-colors/. | D2: Email correspondence with Herman Miller, Culture/Language Resources Director, Washoe Tribe of Nevada and California (Oct. 16, 2024) (on file with the author) | E2: Herman
A3: 1 | B3: 2 | D3: Claire Cudahy, “Washoe youth follow ancestors’ footsteps in Hope Valley,” Tahoe Daily Tribune (Jan. 25, 2018), https://www.tahoedailytribune.com/news/local/washoe-youth-follow-ancestors-footsteps-in-hope-valley-video/ | E3: Cudahy
A4: 1 | B4: 3 | D4: U.S. Forest Service, Carson Ranger District, East Carson River Strategy, 4-5 (July 2007), http://www.theanglersedge.com/downloads/East_Carson_River_Strategy_061907.pdf | E4: Carson
A5: 1 | B5: 4 | D5: The Washoe Tribe of Nevada and California, WA SHE SHU: “The Washoe People” Past and Present (2009), https://www.fs.usda.gov/Internet/FSE_DOCUMENTS/stelprdb5251066.pdf | E5: Washoe USDA
A6: 1 | B6: 5 | D6: Washoe Tribe of California and Nevada, Washoe History: A Brief Summary (2020), https://washoetribe.us/aboutpage/4-Page-washoe-history | E6: Washoe History
A7: 2 | B7: 1 | C7: Frank Tortorich, Jr., The Opening of the Carson River Route, 18 Overland Journal 1, 22 (Spring 2000); Jeff Munson, “Emigrant Trail tour promises spectacular colors,” Tahoe Daily Tribune (Oct. 12, 2005), https://www.tahoedailytribune.com/news/emigrant-trail-tour-promises-spectacular-colors/. | D7: Frank Tortorich, Jr., The Opening of the Carson River Route, 18 Overland Journal 1, 22 (Spring 2000) | E7: Tortorich | G7: {=IF(E7:E735="", "", COUNTIFS(E$7:E735, E$7:E735, ROW(E$7:E735), "<="&ROW(E$7:E735)))} -> 1 | H7: {=IF(G7:G735=1, COUNTIFS(G$7:G735, 1, ROW(G$7:G735), "<="&ROW(G$7:G735)), "")} -> 1
A8: 2 | B8: 2 | D8: Jeff Munson, “Emigrant Trail tour promises spectacular colors,” Tahoe Daily Tribune (Oct. 12, 2005), https://www.tahoedailytribune.com/news/emigrant-trail-tour-promises-spectacular-colors/ | E8: Munson | G8: 1 | H8: 2
A9: 3 | B9: 1 | C9: For the Forest Service’s most current Winter Recreation Map for Hope Valley and surrounding areas, see https://www.fs.usda.gov/Internet/FSE_DOCUMENTS/stelprdb5294291.pdf. | D9: https://www.fs.usda.gov/Internet/FSE_DOCUMENTS/stelprdb5294291.pdf. | E9: Hope Valley Recreation | G9: 1 | H9: 3
A10: 4 | B10: 1 | C10: Memorandum of Opinion and Order, Friends of Hope Valley v. U.S. Forest Serv., No. 2:00-cv-01900-DFL-KJM, 2 (E.D. Cal. Sept. 30, 2004). | D10: Memorandum of Opinion and Order, Friends of Hope Valley v. U.S. Forest Serv., No. 2:00-cv-01900-DFL-KJM, 2 (E.D. Cal. Sept. 30, 2004) | E10: Memorandum | G10: 1 | H10: 4
A11: 5 | B11: 1 | C11: Memorandum of Opinion and Order, Friends of Hope Valley v. U.S. Forest Serv., No. 2:00-cv-01900-DFL-KJM, 6 (E.D. Cal. Sept. 30, 2004). | D11: Memorandum of Opinion and Order, Friends of Hope Valley v. U.S. Forest Serv., No. 2:00-cv-01900-DFL-KJM, 6 (E.D. Cal. Sept. 30, 2004) | E11: Memorandum | G11: 2
A12: 6 | B12: 1 | C12: Friends of Hope Valley v. U.S. Forest Service, 203 Fed. Appx. 883 (9th Cir. 2006) (unpublished). | D12: Friends of Hope Valley v. U.S. Forest Service, 203 Fed. Appx. 883 (9th Cir. 2006) (unpublished) | E12: Friends of Hope Valley v US Forest Service | G12: 1 | H12: 5
A13: 7 | B13: 1 | C13: Id. The APA is found at 5 U.S.C. §§ 551-553, 701-706. This Article is concerned with only APA remands. There are, of course, many other types of remands (to administrative law judges, bankruptcy courts, state courts, and so on), and in a few footnotes I have noted ways in which jurisprudence concerning such other remands is relevant to the administrative-remand rule. See infra notes 113, 151-153. | D13: Id. | E13: Friends of Hope Valley v US Forest Service | G13: 2
A14: 7 | B14: 2 | D14: 5 U.S.C. §§ 551-553, 701-706 | E14: APA | G14: 1 | H14: 6
A15: 7 | B15: 3 | D15: infra notes 113, 151-153 | E15: Infra Notes 113, 151-153 | G15: 1 | H15: 7
A16: 8 | B16: 1 | C16: Friends of Hope Valley, 203 Fed. Appx. at 883 (citing Alsea Valley Alliance v. Dep’t of Commerce, 358 F.3d 1181, 1184 (9th Cir. 2004)). | D16: Friends of Hope Valley, 203 Fed. Appx. at 883 | E16: Friends of Hope Valley v US Forest Service | G16: 3
A17: 8 | B17: 2 | D17: Alsea Valley Alliance v. Dep’t of Commerce, 358 F.3d 1181, 1184 (9th Cir. 2004) | E17: Alsea Valley Alliance v Dep't of Commerce | G17: 1 | H17: 8
A18: 9 | B18: 1 | C18: Alsea Valley Alliance, 358 F.3d at 1184 (emphasis removed). For more detail on section 1291, see infra Part I.B. Also, as infra note 23 explains, some courts and commentators conceive of the rule as being narrower: A decision remanding an agency action is not final and appealable, and an appeal by the agency is an “exception” to that rule instead of part of the rule itself. | D18: Alsea Valley Alliance, 358 F.3d at 1184 | E18: Alsea Valley Alliance v Dep't of Commerce | G18: 2
A19: 9 | B19: 2 | D19: infra Part I.B | E19: Infra Part IB | G19: 1 | H19: 9
A20: 9 | B20: 3 | D20: infra note 23 | E20: Infra Note 23 | G20: 1 | H20: 10
A21: 10 | B21: 1 | C21: The Tenth Circuit coined the term “administrative-remand rule,” and as of 2021, it was “unique” to that circuit. C.W. by and through B.W. v. Denver Cnty. Sch. Dist. No. 1, 994 F.3d 1215, 1220 n.2 (10th Cir. 2021). However, at least two other courts have since started to use that term. See Montana Env’t Info. Ctr. v. Haaland, No. 22-36002, 2023 WL 8166779, at *1 (9th Cir. Nov. 24, 2023); DCOR, LLC v. U.S. Dep’t of the Interior, No. 3:21-CV-00120-N, 2023 WL 8628322, at *1 (N.D. Tex. Dec. 13, 2023). | D21: C.W. by and through B.W. v. Denver Cnty. Sch. Dist. No. 1, 994 F.3d 1215, 1220 n.2 (10th Cir. 2021) | E21: Denver Cnty | G21: 1 | H21: 11
A22: 10 | B22: 2 | D22: Montana Env’t Info. Ctr. v. Haaland, No. 22-36002, 2023 WL 8166779, at *1 (9th Cir. Nov. 24, 2023) | E22: Montana Env't Info CTR | G22: 1 | H22: 12
A23: 10 | B23: 3 | D23: DCOR, LLC v. U.S. Dep’t of the Interior, No. 3:21-CV-00120-N, 2023 WL 8628322, at *1 (N.D. Tex. Dec. 13, 2023) | E23: Dcor | G23: 1 | H23: 13
A24: 11 | B24: 1 | C24: Part I, infra, discusses this case law in detail. Notably, the rise of the administrative-remand rule coincided, unsurprisingly, with the rise of the administrative state. For more on the latter, see, e.g., Jon D. Michaels, Constitutional Coup: Privatization’s Threat to the American Republic, 21-77 (2017); Developments in the Law—Presidential Authority, V. Executive Appointments, 125 Harv. L. Rev. 2135, 2138 (2012); Daniel E. Ho & Erica L. Ross, Did Liberal Justices Invent the Standing Doctrine? An Empirical Study of the Evolution of Standing, 1921-2006, 62 Stan. L. Rev. 591, 647 & n.231 (2010); William S. Jordan, III, Judges, Ideology, and Policy in the Administrative State: Lessons from A Decade of Hard Look Remands of EPA Rules, 53 Admin. L. Rev. 45, 46 (2001). | D24: Part I, infra | E24: Infra Part I | G24: 1 | H24: 14
A25: 1 | D25: Jon D. Michaels, Constitutional Coup: Privatization’s Threat to the American Republic, 21-77 (2017) | E25: Michaels | G25: 1 | H25: 15
A26: 11 | B26: 2 | D26: Developments in the Law—Presidential Authority, V. Executive Appointments, 125 Harv. L. Rev. 2135, 2138 (2012) | E26: Developments | G26: 1 | H26: 16
A27: 11 | B27: 3 | D27: Daniel E. Ho & Erica L. Ross, Did Liberal Justices Invent the Standing Doctrine? An Empirical Study of the Evolution of Standing, 1921-2006, 62 Stan. L. Rev. 591, 647 & n.231 (2010) | E27: Ho | G27: 1 | H27: 17
A28: 11 | B28: 4 | D28: William S. Jordan, III, Judges, Ideology, and Policy in the Administrative State: Lessons from A Decade of Hard Look Remands of EPA Rules, 53 Admin. L. Rev. 45, 46 (2001) | E28: Jordan | G28: 1 | H28: 18
A29: 12 | B29: 1 | C29: The Court came closest to considering the rule in Sullivan v. Finkelstein, 496 U.S. 617, 625 (1990), which interpreted a specific finality statute to permit appeals of district court remands in Social Security cases. See infra notes 89-97 and accompanying text pp. 17-19 (discussing Finkelstein in detail). | D29: Sullivan v. Finkelstein, 496 U.S. 617, 625 (1990) | E29: Finkelstein | G29: 1 | H29: 19
A30: 12 | B30: 2 | D30: infra notes 89-97 and accompanying text pp. 17-19 | E30: Infra Notes 89-97 and Accompanying Text Pp 17-19 | G30: 1 | H30: 20
A31: 13 | B31: 1 | C31: Professor Bryan Lammon at the University of Toledo College of Law has written most extensively about the administrative-remand rule, though in the more general context of finality and appellate jurisdiction. See Bryan Lammon, Finality, Appealability, and the Scope of Interlocutory Review, 93 Wash. L. Rev. 1809, 1834-37 (2018); Bryan Lammon, Dizzying Gillespie: The Exaggerated Death of the Balancing Approach and the Inescapable Allure of Flexibility in Appellate Jurisdiction, 51 U. Rich. L. Rev. 371, 386-93 (2017). The rule has received passing attention in other scholarship. See, e.g., Harold J. Krent, Situating Structural Challenges to Agency Authority Within the Framework of the Finality Principle, 98 Ind. L.J. Supplement 1, 10 n.73 (2023); Jennifer L. Biever & Ana Maria Gutierrez, The Uncertain Question of Remedies Should a Challenge Prevail, 2016 NO. 5 RMMLF-INST PAPER NO. 13, 28-29 (2016); Michele D. Lynch, Remands Are A Consequence of Administrative Law, So Why Are We All So Frustrated?, 23 Tul. J. Int’l & Comp. L. 383, 392 (2015). Finally, a few treatises discuss the rule. See, e.g., Federal Practice & Procedure, § 3914.32 Orders Prior to Trial—Administrative Review, 15B Fed. Prac. & Proc. Juris. § 3914.32 (2d ed. June 2024 Update); Federal Practice & Procedure, § 3903 Pragmatic Finality, 15A Fed. Prac. & Proc. Juris. § 3913 (3d ed. June 2024 Update); see also, e.g., 73A C.J.S. Pub. Admin. Law & Proc. § 561 (May 2024); Fed. Ct. App. Manual § 2:3 (7th ed. May 2024). | D31: Bryan Lammon, Finality, Appealability, and the Scope of Interlocutory Review, 93 Wash. L. Rev. 1809, 1834-37 (2018) | E31: Lammon Appealability | G31: 1 | H31: 21
A32: 13 | B32: 2 | D32: Bryan Lammon, Dizzying Gillespie: The Exaggerated Death of the Balancing Approach and the Inescapable Allure of Flexibility in Appellate Jurisdiction, 51 U. Rich. L. Rev. 371, 386-93 (2017) | E32: Lammon Dizzying | G32: 1 | H32: 22
A33: 13 | B33: 3 | D33: Harold J. Krent, Situating Structural Challenges to Agency Authority Within the Framework of the Finality Principle, 98 Ind. L.J. Supplement 1, 10 n.73 (2023) | E33: Krent | G33: 1 | H33: 23
A34: 13 | B34: 4 | D34: Jennifer L. Biever & Ana Maria Gutierrez, The Uncertain Question of Remedies Should a Challenge Prevail, 2016 NO. 5 RMMLF-INST PAPER NO. 13, 28-29 (2016) | E34: Biever | G34: 1 | H34: 24
A35: 13 | B35: 5 | D35: Michele D. Lynch, Remands Are A Consequence of Administrative Law, So Why Are We All So Frustrated?, 23 Tul. J. Int’l & Comp. L. 383, 392 (2015) | E35: Lynch | G35: 1 | H35: 25
A36: 13 | B36: 6 | D36: Federal Practice & Procedure, § 3914.32 Orders Prior to Trial—Administrative Review, 15B Fed. Prac. & Proc. Juris. § 3914.32 (2d ed. June 2024 Update) | E36: Federal Practice 3914 32 | G36: 1 | H36: 26
A37: 13 | B37: 7 | D37: Federal Practice & Procedure, § 3903 Pragmatic Finality, 15A Fed. Prac. & Proc. Juris. § 3913 (3d ed. June 2024 Update) | E37: Federal Practice 3903 | G37: 1 | H37: 27
A38: 13 | B38: 8 | D38: 73A C.J.S. Pub. Admin. Law & Proc. § 561 (May 2024) | E38: 73a CJS | G38: 1 | H38: 28
A39: 13 | B39: 9 | D39: Fed. Ct. App. Manual § 2:3 (7th ed. May 2024) | E39: Fed Ct | G39: 1 | H39: 29
A40: 14 | B40: 1 | C40: Section 1291 is Congress’ enshrinement of the final-judgment rule. See infra notes 39-51 and accompanying text (discussing the final-judgment rule in detail). | D40: infra notes 39-51 and accompanying text | E40: Infra Notes 39-51 and Accompanying Text | G40: 1 | H40: 30
...

Sheet Sourcepull (Old)
A1: ID | B1: Short Name | C1: Fn# | D1: Full Source Citation | F1: Sourcepull File Name (DNE) | G1: Sourcepuller | H1: Completed? | I1: All Pincites (for books) | J1: Consecutively Paginated? | K1: Subseqent History / Negative Treatment? | L1: Location of Source (Green, Crown, etc.) | M1: ILL or Recall and Date of Request (books only) | N1: Problems or Comments | O1: Sourcepull checked by SE?
B2: =IFERROR(__xludf.DUMMYFUNCTION("FILTER('Raw Output'!E:E, 'Raw Output'!$G:$G=1)"),"Source Name") -> Source Name | C2: =IFERROR(__xludf.DUMMYFUNCTION("FILTER(TEXT('Raw Output'!A:A, ""000""), 'Raw Output'!$G:$G=1)"),"001") -> 001 | D2: =IFERROR(__xludf.DUMMYFUNCTION("FILTER('Raw Output'!D:D, 'Raw Output'!$G:$G=1)"),"Citation Text") -> Citation Text | E2: {=if($B$2:$B952 <> "", hyperlink("https://drive.google.com/drive/search?q=parent:" & Properties!$C$8 & "%20" & char(34) & $F$2:$F952 & char(34), "➔"), "")} -> ➔ | F2: {=if($B$2:$B952<>"","SP-"&$A$2:$A952 &"-"&$B$2:$B952&".pdf", "")} -> SP--Source Name.pdf
A3: 001 | B3: =IFERROR(__xludf.DUMMYFUNCTION("""COMPUTED_VALUE"""),"Tortorich") -> Tortorich | C3: =IFERROR(__xludf.DUMMYFUNCTION("""COMPUTED_VALUE"""),"002") -> 002 | D3: =IFERROR(__xludf.DUMMYFUNCTION("""COMPUTED_VALUE"""),"Frank Tortorich, Jr., The Opening of the Carson River Route, 18 Overland Journal 1, 22 (Spring 2000)") -> Frank Tortorich, Jr., The Opening of the Carson River Route, 18 Overland Journal 1, 22 (Spring 2000) | E3: ➔ | F3: SP-001-Tortorich.pdf | G3: ME
A4: 002 | B4: =IFERROR(__xludf.DUMMYFUNCTION("""COMPUTED_VALUE"""),"Munson") -> Munson | C4: =IFERROR(__xludf.DUMMYFUNCTION("""COMPUTED_VALUE"""),"002") -> 002 | D4: =IFERROR(__xludf.DUMMYFUNCTION("""COMPUTED_VALUE"""),"Jeff Munson, “Emigrant Trail tour promises spectacular colors,” Tahoe Daily Tribune (Oct. 12, 2005), https://www.tahoedailytribune.com/news/emigrant-trail-tour-promises-spectacular-colors/") -> Jeff Munson, “Emigrant Trail tour promises spectacular colors,” Tahoe Daily Tribune (Oct. 12, 2005), https://www.tahoedailytribune.com/news/emigrant-trail-tour-promises-spectacular-colors/ | E4: ➔ | F4: SP-002-Munson.pdf | G4: ME
A5: 003 | B5: =IFERROR(__xludf.DUMMYFUNCTION("""COMPUTED_VALUE"""),"Hope Valley Recreation") -> Hope Valley Recreation | C5: =IFERROR(__xludf.DUMMYFUNCTION("""COMPUTED_VALUE"""),"003") -> 003 | D5: =IFERROR(__xludf.DUMMYFUNCTION("""COMPUTED_VALUE"""),"https://www.fs.usda.gov/Internet/FSE_DOCUMENTS/stelprdb5294291.pdf.") -> https://www.fs.usda.gov/Internet/FSE_DOCUMENTS/stelprdb5294291.pdf. | E5: ➔ | F5: SP-003-Hope Valley Recreation.pdf | G5: ME
A6: 004 | B6: =IFERROR(__xludf.DUMMYFUNCTION("""COMPUTED_VALUE"""),"Memorandum") -> Memorandum | C6: =IFERROR(__xludf.DUMMYFUNCTION("""COMPUTED_VALUE"""),"004") -> 004 | D6: =IFERROR(__xludf.DUMMYFUNCTION("""COMPUTED_VALUE"""),"Memorandum of Opinion and Order, Friends of Hope Valley v. U.S. Forest Serv., No. 2:00-cv-01900-DFL-KJM, 2 (E.D. Cal. Sept. 30, 2004)") -> Memorandum of Opinion and Order, Friends of Hope Valley v. U.S. Forest Serv., No. 2:00-cv-01900-DFL-KJM, 2 (E.D. Cal. Sept. 30, 2004) | E6: ➔ | F6: SP-004-Memorandum.pdf | G6: ME
A7: 005 | B7: =IFERROR(__xludf.DUMMYFUNCTION("""COMPUTED_VALUE"""),"Friends of Hope Valley v US Forest Service") -> Friends of Hope Valley v US Forest Service | C7: =IFERROR(__xludf.DUMMYFUNCTION("""COMPUTED_VALUE"""),"006") -> 006 | D7: =IFERROR(__xludf.DUMMYFUNCTION("""COMPUTED_VALUE"""),"Friends of Hope Valley v. U.S. Forest Service, 203 Fed. Appx. 883 (9th Cir. 2006) (unpublished)") -> Friends of Hope Valley v. U.S. Forest Service, 203 Fed. Appx. 883 (9th Cir. 2006) (unpublished) | E7: ➔ | F7: SP-005-Friends of Hope Valley v US Forest Service.pdf | G7: ME
A8: 006 | B8: =IFERROR(__xludf.DUMMYFUNCTION("""COMPUTED_VALUE"""),"APA") -> APA | C8: =IFERROR(__xludf.DUMMYFUNCTION("""COMPUTED_VALUE"""),"007") -> 007 | D8: =IFERROR(__xludf.DUMMYFUNCTION("""COMPUTED_VALUE"""),"5 U.S.C. §§ 551-553, 701-706") -> 5 U.S.C. §§ 551-553, 701-706 | E8: ➔ | F8: SP-006-APA.pdf | G8: ME
A9: 007 | B9: =IFERROR(__xludf.DUMMYFUNCTION("""COMPUTED_VALUE"""),"Infra Notes 113, 151-153") -> Infra Notes 113, 151-153 | C9: =IFERROR(__xludf.DUMMYFUNCTION("""COMPUTED_VALUE"""),"007") -> 007 | D9: =IFERROR(__xludf.DUMMYFUNCTION("""COMPUTED_VALUE"""),"infra notes 113, 151-153") -> infra notes 113, 151-153 | E9: ➔ | F9: SP-007-Infra Notes 113, 151-153.pdf | G9: ME
A10: 008 | B10: =IFERROR(__xludf.DUMMYFUNCTION("""COMPUTED_VALUE"""),"Alsea Valley Alliance v Dep't of Commerce") -> Alsea Valley Alliance v Dep't of Commerce | C10: =IFERROR(__xludf.DUMMYFUNCTION("""COMPUTED_VALUE"""),"008") -> 008 | D10: =IFERROR(__xludf.DUMMYFUNCTION("""COMPUTED_VALUE"""),"Alsea Valley Alliance v. Dep’t of Commerce, 358 F.3d 1181, 1184 (9th Cir. 2004)") -> Alsea Valley Alliance v. Dep’t of Commerce, 358 F.3d 1181, 1184 (9th Cir. 2004) | E10: ➔ | F10: SP-008-Alsea Valley Alliance v Dep't of Commerce.pdf | G10: ME
A11: 009 | B11: =IFERROR(__xludf.DUMMYFUNCTION("""COMPUTED_VALUE"""),"Infra Part IB") -> Infra Part IB | C11: =IFERROR(__xludf.DUMMYFUNCTION("""COMPUTED_VALUE"""),"009") -> 009 | D11: =IFERROR(__xludf.DUMMYFUNCTION("""COMPUTED_VALUE"""),"infra Part I.B") -> infra Part I.B | E11: ➔ | F11: SP-009-Infra Part IB.pdf | G11: ME
A12: 010 | B12: =IFERROR(__xludf.DUMMYFUNCTION("""COMPUTED_VALUE"""),"Infra Note 23") -> Infra Note 23 | C12: =IFERROR(__xludf.DUMMYFUNCTION("""COMPUTED_VALUE"""),"009") -> 009 | D12: =IFERROR(__xludf.DUMMYFUNCTION("""COMPUTED_VALUE"""),"infra note 23") -> infra note 23 | E12: ➔ | F12: SP-010-Infra Note 23.pdf | G12: ME
A13: 011 | B13: =IFERROR(__xludf.DUMMYFUNCTION("""COMPUTED_VALUE"""),"Denver Cnty") -> Denver Cnty | C13: =IFERROR(__xludf.DUMMYFUNCTION("""COMPUTED_VALUE"""),"010") -> 010 | D13: =IFERROR(__xludf.DUMMYFUNCTION("""COMPUTED_VALUE"""),"C.W. by and through B.W. v. Denver Cnty. Sch. Dist. No. 1, 994 F.3d 1215, 1220 n.2 (10th Cir. 2021)") -> C.W. by and through B.W. v. Denver Cnty. Sch. Dist. No. 1, 994 F.3d 1215, 1220 n.2 (10th Cir. 2021) | E13: ➔ | F13: SP-011-Denver Cnty.pdf | G13: ME
A14: 012 | B14: =IFERROR(__xludf.DUMMYFUNCTION("""COMPUTED_VALUE"""),"Montana Env't Info CTR") -> Montana Env't Info CTR | C14: =IFERROR(__xludf.DUMMYFUNCTION("""COMPUTED_VALUE"""),"010") -> 010 | D14: =IFERROR(__xludf.DUMMYFUNCTION("""COMPUTED_VALUE"""),"Montana Env’t Info. Ctr. v. Haaland, No. 22-36002, 2023 WL 8166779, at *1 (9th Cir. Nov. 24, 2023)") -> Montana Env’t Info. Ctr. v. Haaland, No. 22-36002, 2023 WL 8166779, at *1 (9th Cir. Nov. 24, 2023) | E14: ➔ | F14: SP-012-Montana Env't Info CTR.pdf | G14: ME
A15: 013 | B15: =IFERROR(__xludf.DUMMYFUNCTION("""COMPUTED_VALUE"""),"Dcor") -> Dcor | C15: =IFERROR(__xludf.DUMMYFUNCTION("""COMPUTED_VALUE"""),"010") -> 010 | D15: =IFERROR(__xludf.DUMMYFUNCTION("""COMPUTED_VALUE"""),"DCOR, LLC v. U.S. Dep’t of the Interior, No. 3:21-CV-00120-N, 2023 WL 8628322, at *1 (N.D. Tex. Dec. 13, 2023)") -> DCOR, LLC v. U.S. Dep’t of the Interior, No. 3:21-CV-00120-N, 2023 WL 8628322, at *1 (N.D. Tex. Dec. 13, 2023) | E15: ➔ | F15: SP-013-Dcor.pdf | G15: ME
A16: 014 | B16: =IFERROR(__xludf.DUMMYFUNCTION("""COMPUTED_VALUE"""),"Infra Part I") -> Infra Part I | C16: =IFERROR(__xludf.DUMMYFUNCTION("""COMPUTED_VALUE"""),"011") -> 011 | D16: =IFERROR(__xludf.DUMMYFUNCTION("""COMPUTED_VALUE"""),"Part I, infra") -> Part I, infra | E16: ➔ | F16: SP-014-Infra Part I.pdf | G16: ME
A17: 015 | B17: =IFERROR(__xludf.DUMMYFUNCTION("""COMPUTED_VALUE"""),"Michaels") -> Michaels | C17: =IFERROR(__xludf.DUMMYFUNCTION("""COMPUTED_VALUE"""),"001") -> 001 | D17: =IFERROR(__xludf.DUMMYFUNCTION("""COMPUTED_VALUE"""),"Jon D. Michaels, Constitutional Coup: Privatization’s Threat to the American Republic, 21-77 (2017)") -> Jon D. Michaels, Constitutional Coup: Privatization’s Threat to the American Republic, 21-77 (2017) | E17: ➔ | F17: SP-015-Michaels.pdf | G17: ME
A18: 016 | B18: =IFERROR(__xludf.DUMMYFUNCTION("""COMPUTED_VALUE"""),"Developments") -> Developments | C18: =IFERROR(__xludf.DUMMYFUNCTION("""COMPUTED_VALUE"""),"011") -> 011 | D18: =IFERROR(__xludf.DUMMYFUNCTION("""COMPUTED_VALUE"""),"Developments in the Law—Presidential Authority, V. Executive Appointments, 125 Harv. L. Rev. 2135, 2138 (2012)") -> Developments in the Law—Presidential Authority, V. Executive Appointments, 125 Harv. L. Rev. 2135, 2138 (2012) | E18: ➔ | F18: SP-016-Developments.pdf | G18: ME
A19: 017 | B19: =IFERROR(__xludf.DUMMYFUNCTION("""COMPUTED_VALUE"""),"Ho") -> Ho | C19: =IFERROR(__xludf.DUMMYFUNCTION("""COMPUTED_VALUE"""),"011") -> 011 | D19: =IFERROR(__xludf.DUMMYFUNCTION("""COMPUTED_VALUE"""),"Daniel E. Ho & Erica L. Ross, Did Liberal Justices Invent the Standing Doctrine? An Empirical Study of the Evolution of Standing, 1921-2006, 62 Stan. L. Rev. 591, 647 & n.231 (2010)") -> Daniel E. Ho & Erica L. Ross, Did Liberal Justices Invent the Standing Doctrine? An Empirical Study of the Evolution of Standing, 1921-2006, 62 Stan. L. Rev. 591, 647 & n.231 (2010) | E19: ➔ | F19: SP-017-Ho.pdf | G19: ME
A20: 018 | B20: =IFERROR(__xludf.DUMMYFUNCTION("""COMPUTED_VALUE"""),"Jordan") -> Jordan | C20: =IFERROR(__xludf.DUMMYFUNCTION("""COMPUTED_VALUE"""),"011") -> 011 | D20: =IFERROR(__xludf.DUMMYFUNCTION("""COMPUTED_VALUE"""),"William S. Jordan, III, Judges, Ideology, and Policy in the Administrative State: Lessons from A Decade of Hard Look Remands of EPA Rules, 53 Admin. L. Rev. 45, 46 (2001)") -> William S. Jordan, III, Judges, Ideology, and Policy in the Administrative State: Lessons from A Decade of Hard Look Remands of EPA Rules, 53 Admin. L. Rev. 45, 46 (2001) | E20: ➔ | F20: SP-018-Jordan.pdf | G20: ME
A21: 019 | B21: =IFERROR(__xludf.DUMMYFUNCTION("""COMPUTED_VALUE"""),"Finkelstein") -> Finkelstein | C21: =IFERROR(__xludf.DUMMYFUNCTION("""COMPUTED_VALUE"""),"012") -> 012 | D21: =IFERROR(__xludf.DUMMYFUNCTION("""COMPUTED_VALUE"""),"Sullivan v. Finkelstein, 496 U.S. 617, 625 (1990)") -> Sullivan v. Finkelstein, 496 U.S. 617, 625 (1990) | E21: ➔ | F21: SP-019-Finkelstein.pdf | G21: ME
A22: 020 | B22: =IFERROR(__xludf.DUMMYFUNCTION("""COMPUTED_VALUE"""),"Infra Notes 89-97 and Accompanying Text Pp 17-19") -> Infra Notes 89-97 and Accompanying Text Pp 17-19 | C22: =IFERROR(__xludf.DUMMYFUNCTION("""COMPUTED_VALUE"""),"012") -> 012 | D22: =IFERROR(__xludf.DUMMYFUNCTION("""COMPUTED_VALUE"""),"infra notes 89-97 and accompanying text pp. 17-19") -> infra notes 89-97 and accompanying text pp. 17-19 | E22: ➔ | F22: SP-020-Infra Notes 89-97 and Accompanying Text Pp 17-19.pdf | G22: ME
A23: 021 | B23: =IFERROR(__xludf.DUMMYFUNCTION("""COMPUTED_VALUE"""),"Lammon Appealability") -> Lammon Appealability | C23: =IFERROR(__xludf.DUMMYFUNCTION("""COMPUTED_VALUE"""),"013") -> 013 | D23: =IFERROR(__xludf.DUMMYFUNCTION("""COMPUTED_VALUE"""),"Bryan Lammon, Finality, Appealability, and the Scope of Interlocutory Review, 93 Wash. L. Rev. 1809, 1834-37 (2018)") -> Bryan Lammon, Finality, Appealability, and the Scope of Interlocutory Review, 93 Wash. L. Rev. 1809, 1834-37 (2018) | E23: ➔ | F23: SP-021-Lammon Appealability.pdf | G23: ME
A24: 022 | B24: =IFERROR(__xludf.DUMMYFUNCTION("""COMPUTED_VALUE"""),"Lammon Dizzying") -> Lammon Dizzying | C24: =IFERROR(__xludf.DUMMYFUNCTION("""COMPUTED_VALUE"""),"013") -> 013 | D24: =IFERROR(__xludf.DUMMYFUNCTION("""COMPUTED_VALUE"""),"Bryan Lammon, Dizzying Gillespie: The Exaggerated Death of the Balancing Approach and the Inescapable Allure of Flexibility in Appellate Jurisdiction, 51 U. Rich. L. Rev. 371, 386-93 (2017)") -> Bryan Lammon, Dizzying Gillespie: The Exaggerated Death of the Balancing Approach and the Inescapable Allure of Flexibility in Appellate Jurisdiction, 51 U. Rich. L. Rev. 371, 386-93 (2017) | E24: ➔ | F24: SP-022-Lammon Dizzying.pdf | G24: ME
A25: 023 | B25: =IFERROR(__xludf.DUMMYFUNCTION("""COMPUTED_VALUE"""),"Krent") -> Krent | C25: =IFERROR(__xludf.DUMMYFUNCTION("""COMPUTED_VALUE"""),"013") -> 013 | D25: =IFERROR(__xludf.DUMMYFUNCTION("""COMPUTED_VALUE"""),"Harold J. Krent, Situating Structural Challenges to Agency Authority Within the Framework of the Finality Principle, 98 Ind. L.J. Supplement 1, 10 n.73 (2023)") -> Harold J. Krent, Situating Structural Challenges to Agency Authority Within the Framework of the Finality Principle, 98 Ind. L.J. Supplement 1, 10 n.73 (2023) | E25: ➔ | F25: SP-023-Krent.pdf | G25: ME
A26: 024 | B26: =IFERROR(__xludf.DUMMYFUNCTION("""COMPUTED_VALUE"""),"Biever") -> Biever | C26: =IFERROR(__xludf.DUMMYFUNCTION("""COMPUTED_VALUE"""),"013") -> 013 | D26: =IFERROR(__xludf.DUMMYFUNCTION("""COMPUTED_VALUE"""),"Jennifer L. Biever & Ana Maria Gutierrez, The Uncertain Question of Remedies Should a Challenge Prevail, 2016 NO. 5 RMMLF-INST PAPER NO. 13, 28-29 (2016)") -> Jennifer L. Biever & Ana Maria Gutierrez, The Uncertain Question of Remedies Should a Challenge Prevail, 2016 NO. 5 RMMLF-INST PAPER NO. 13, 28-29 (2016) | E26: ➔ | F26: SP-024-Biever.pdf | G26: ME
A27: 025 | B27: =IFERROR(__xludf.DUMMYFUNCTION("""COMPUTED_VALUE"""),"Lynch") -> Lynch | C27: =IFERROR(__xludf.DUMMYFUNCTION("""COMPUTED_VALUE"""),"013") -> 013 | D27: =IFERROR(__xludf.DUMMYFUNCTION("""COMPUTED_VALUE"""),"Michele D. Lynch, Remands Are A Consequence of Administrative Law, So Why Are We All So Frustrated?, 23 Tul. J. Int’l & Comp. L. 383, 392 (2015)") -> Michele D. Lynch, Remands Are A Consequence of Administrative Law, So Why Are We All So Frustrated?, 23 Tul. J. Int’l & Comp. L. 383, 392 (2015) | E27: ➔ | F27: SP-025-Lynch.pdf | G27: ME
A28: 026 | B28: =IFERROR(__xludf.DUMMYFUNCTION("""COMPUTED_VALUE"""),"Federal Practice 3914 32") -> Federal Practice 3914 32 | C28: =IFERROR(__xludf.DUMMYFUNCTION("""COMPUTED_VALUE"""),"013") -> 013 | D28: =IFERROR(__xludf.DUMMYFUNCTION("""COMPUTED_VALUE"""),"Federal Practice & Procedure, § 3914.32 Orders Prior to Trial—Administrative Review, 15B Fed. Prac. & Proc. Juris. § 3914.32 (2d ed. June 2024 Update)") -> Federal Practice & Procedure, § 3914.32 Orders Prior to Trial—Administrative Review, 15B Fed. Prac. & Proc. Juris. § 3914.32 (2d ed. June 2024 Update) | E28: ➔ | F28: SP-026-Federal Practice 3914 32.pdf | G28: ME
A29: 027 | B29: =IFERROR(__xludf.DUMMYFUNCTION("""COMPUTED_VALUE"""),"Federal Practice 3903") -> Federal Practice 3903 | C29: =IFERROR(__xludf.DUMMYFUNCTION("""COMPUTED_VALUE"""),"013") -> 013 | D29: =IFERROR(__xludf.DUMMYFUNCTION("""COMPUTED_VALUE"""),"Federal Practice & Procedure, § 3903 Pragmatic Finality, 15A Fed. Prac. & Proc. Juris. § 3913 (3d ed. June 2024 Update)") -> Federal Practice & Procedure, § 3903 Pragmatic Finality, 15A Fed. Prac. & Proc. Juris. § 3913 (3d ed. June 2024 Update) | E29: ➔ | F29: SP-027-Federal Practice 3903.pdf | G29: ME
A30: 028 | B30: =IFERROR(__xludf.DUMMYFUNCTION("""COMPUTED_VALUE"""),"73a CJS") -> 73a CJS | C30: =IFERROR(__xludf.DUMMYFUNCTION("""COMPUTED_VALUE"""),"013") -> 013 | D30: =IFERROR(__xludf.DUMMYFUNCTION("""COMPUTED_VALUE"""),"73A C.J.S. Pub. Admin. Law & Proc. § 561 (May 2024)") -> 73A C.J.S. Pub. Admin. Law & Proc. § 561 (May 2024) | E30: ➔ | F30: SP-028-73a CJS.pdf | G30: ME
A31: 029 | B31: =IFERROR(__xludf.DUMMYFUNCTION("""COMPUTED_VALUE"""),"Fed Ct") -> Fed Ct | C31: =IFERROR(__xludf.DUMMYFUNCTION("""COMPUTED_VALUE"""),"013") -> 013 | D31: =IFERROR(__xludf.DUMMYFUNCTION("""COMPUTED_VALUE"""),"Fed. Ct. App. Manual § 2:3 (7th ed. May 2024)") -> Fed. Ct. App. Manual § 2:3 (7th ed. May 2024) | E31: ➔ | F31: SP-029-Fed Ct.pdf | G31: ME
A32: 030 | B32: =IFERROR(__xludf.DUMMYFUNCTION("""COMPUTED_VALUE"""),"Infra Notes 39-51 and Accompanying Text") -> Infra Notes 39-51 and Accompanying Text | C32: =IFERROR(__xludf.DUMMYFUNCTION("""COMPUTED_VALUE"""),"014") -> 014 | D32: =IFERROR(__xludf.DUMMYFUNCTION("""COMPUTED_VALUE"""),"infra notes 39-51 and accompanying text") -> infra notes 39-51 and accompanying text | E32: ➔ | F32: SP-030-Infra Notes 39-51 and Accompanying Text.pdf | G32: ME
A33: 031 | B33: =IFERROR(__xludf.DUMMYFUNCTION("""COMPUTED_VALUE"""),"Infra Notes 46-48 and Accompanying Text") -> Infra Notes 46-48 and Accompanying Text | C33: =IFERROR(__xludf.DUMMYFUNCTION("""COMPUTED_VALUE"""),"015") -> 015 | D33: =IFERROR(__xludf.DUMMYFUNCTION("""COMPUTED_VALUE"""),"infra notes 46-48 and accompanying text") -> infra notes 46-48 and accompanying text | E33: ➔ | F33: SP-031-Infra Notes 46-48 and Accompanying Text.pdf | G33: ME
A34: 032 | B34: =IFERROR(__xludf.DUMMYFUNCTION("""COMPUTED_VALUE"""),"Pueblo of Sandia v Babbitt") -> Pueblo of Sandia v Babbitt | C34: =IFERROR(__xludf.DUMMYFUNCTION("""COMPUTED_VALUE"""),"016") -> 016 | D34: =IFERROR(__xludf.DUMMYFUNCTION("""COMPUTED_VALUE"""),"Pueblo of Sandia v. Babbitt, 231 F.3d 878, 880 (D.C. Cir. 2000)") -> Pueblo of Sandia v. Babbitt, 231 F.3d 878, 880 (D.C. Cir. 2000) | E34: ➔ | F34: SP-032-Pueblo of Sandia v Babbitt.pdf | G34: ME
A35: 033 | B35: =IFERROR(__xludf.DUMMYFUNCTION("""COMPUTED_VALUE"""),"CTR for Biological Diversity v Bureau of Land MGMT") -> CTR for Biological Diversity v Bureau of Land MGMT | C35: =IFERROR(__xludf.DUMMYFUNCTION("""COMPUTED_VALUE"""),"017") -> 017 | D35: =IFERROR(__xludf.DUMMYFUNCTION("""COMPUTED_VALUE"""),"Ctr. for Biological Diversity v. Bureau of Land Mgmt., 69 F.4th 588, 597-98 (9th Cir. 2023) (Friedland and Bennett, JJ., concurring)") -> Ctr. for Biological Diversity v. Bureau of Land Mgmt., 69 F.4th 588, 597-98 (9th Cir. 2023) (Friedland and Bennett, JJ., concurring) | E35: ➔ | F35: SP-033-CTR for Biological Diversity v Bureau of Land MGMT.pdf | G35: ME
A36: 034 | B36: =IFERROR(__xludf.DUMMYFUNCTION("""COMPUTED_VALUE"""),"NY Legal Assistance GRP v Cardona") -> NY Legal Assistance GRP v Cardona | C36: =IFERROR(__xludf.DUMMYFUNCTION("""COMPUTED_VALUE"""),"017") -> 017 | D36: =IFERROR(__xludf.DUMMYFUNCTION("""COMPUTED_VALUE"""),"N.Y. Legal Assistance Grp. v. Cardona, No. 21-888-CV, 2024 WL 64220, at *3-4 (2d Cir. Jan. 5, 2024)") -> N.Y. Legal Assistance Grp. v. Cardona, No. 21-888-CV, 2024 WL 64220, at *3-4 (2d Cir. Jan. 5, 2024) | E36: ➔ | F36: SP-034-NY Legal Assistance GRP v Cardona.pdf | G36: ME
A37: 035 | B37: =IFERROR(__xludf.DUMMYFUNCTION("""COMPUTED_VALUE"""),"Infra Notes 132-192 and Accompanying Text") -> Infra Notes 132-192 and Accompanying Text | C37: =IFERROR(__xludf.DUMMYFUNCTION("""COMPUTED_VALUE"""),"018") -> 018 | D37: =IFERROR(__xludf.DUMMYFUNCTION("""COMPUTED_VALUE"""),"infra notes 132-192 and accompanying text") -> infra notes 132-192 and accompanying text | E37: ➔ | F37: SP-035-Infra Notes 132-192 and Accompanying Text.pdf | G37: ME
A38: 036 | B38: =IFERROR(__xludf.DUMMYFUNCTION("""COMPUTED_VALUE"""),"Infra Notes 193-194") -> Infra Notes 193-194 | C38: =IFERROR(__xludf.DUMMYFUNCTION("""COMPUTED_VALUE"""),"019") -> 019 | D38: =IFERROR(__xludf.DUMMYFUNCTION("""COMPUTED_VALUE"""),"infra notes 193-194, 262-270 and accompanying text") -> infra notes 193-194, 262-270 and accompanying text | E38: ➔ | F38: SP-036-Infra Notes 193-194.pdf | G38: ME
A39: 037 | B39: =IFERROR(__xludf.DUMMYFUNCTION("""COMPUTED_VALUE"""),"Clopton") -> Clopton | C39: =IFERROR(__xludf.DUMMYFUNCTION("""COMPUTED_VALUE"""),"020") -> 020 | D39: =IFERROR(__xludf.DUMMYFUNCTION("""COMPUTED_VALUE"""),"Zachary D. Clopton & Katherine Shaw, Public Law Litigation and Electoral Time, 2023 Wis. L. Rev. 1513, 1521–22 (2023)") -> Zachary D. Clopton & Katherine Shaw, Public Law Litigation and Electoral Time, 2023 Wis. L. Rev. 1513, 1521–22 (2023) | E39: ➔ | F39: SP-037-Clopton.pdf | G39: ME
A40: 038 | B40: =IFERROR(__xludf.DUMMYFUNCTION("""COMPUTED_VALUE"""),"Jackson") -> Jackson | C40: =IFERROR(__xludf.DUMMYFUNCTION("""COMPUTED_VALUE"""),"021") -> 021 | D40: =IFERROR(__xludf.DUMMYFUNCTION("""COMPUTED_VALUE"""),"Jackson v. Bd. of Civ. Serv. Comm’rs of City of Los Angeles, 99 Cal. App. 5th 648, 655-62, 318 Cal. Rptr. 3d 79 (2024)") -> Jackson v. Bd. of Civ. Serv. Comm’rs of City of Los Angeles, 99 Cal. App. 5th 648, 655-62, 318 Cal. Rptr. 3d 79 (2024) | E40: ➔ | F40: SP-038-Jackson.pdf | G40: ME
...

Sheet CC
A1: Source | F1: Drive | I1: Round 1 | Q1: Round 2
A2: Short Name | B2: ID | C2: SP String (DNE) | D2: R1 String (DNE) | E2: R2 String (DNE) | F2: SP | G2: R1 | H2: R2 | I2: MEM | J2: Fn# | K2: Cite# | L2: Supports? | M2: Citation Elements | N2: MEM Comments | O2: SE Response | P2: Kickback Response | Q2: MEM | R2: Fn# | S2: Cite# | T2: Supports? | U2: Citation Elements | V2: MEM Comments | W2: SE Response | X2: Kickback Response
A3: Keep this row hidden / do not edit! | B3: {=IF($A$3:$A11<>"", XLOOKUP($A$3:$A11, Sourcepull!$B$3:$B11, Sourcepull!$A$3:$A11, ""), "")} | C3: {=if($A$3:$A11<>"","SP-"&$B$3:$B11&"-"&$A$3:$A11&".pdf", "")} -> SP--Keep this row hidden / do not edit!.pdf | D3: {=if($J$3:$J11<>"","R1-"&$J$3:$J11&"-"&$K$3:$K11&"-"&$B$3:$B11&"-"&$A$3:$A11&".pdf", "")} | E3: {=if($R$3:$R11<>"","R2-"&$R$3:$R11&"-"&$S$3:$S11&"-"&$B$3:$B11&"-"&$A$3:$A11&".pdf", "")} | F3: {=if($C$3:$C11 <> "", hyperlink("https://drive.google.com/drive/search?q=parent:" & Properties!$C$8 & "%20" & char(34) & $C$3:$C11 & char(34), "➔"), "")} -> ➔ | G3: {=if($D$3:$D11 <> "", hyperlink("https://drive.google.com/drive/search?q=parent:" & Properties!$C$9 & "%20" & char(34) & $D$3:$D11 & char(34), "➔"), "")} | H3: {=if($E$3:$E11 <> "", hyperlink("https://drive.google.com/drive/search?q=parent:" & Properties!$C$10 & "%20" & char(34) & $E$3:$E11 & char(34), "➔"), "")}

Sheet Sourcepull
A1: ID | B1: Short Name | C1: Fn# | D1: Full Source Citation | F1: Sourcepull File Name (DNE) | G1: Sourcepuller | H1: Completed? | I1: All Pincites (for books) | J1: Consecutively Paginated? | K1: Subseqent History / Negative Treatment? | L1: Location of Source (Green, Crown, etc.) | M1: ILL or Recall and Date of Request (books only) | N1: Problems or Comments | O1: Sourcepull checked by SE?
B2: =IFERROR(__xludf.DUMMYFUNCTION("FILTER('Raw Output'!E:E, 'Raw Output'!$G:$G=1)"),"#REF!") -> #REF! | D2: =IFERROR(__xludf.DUMMYFUNCTION("FILTER('Raw Output'!D:D, 'Raw Output'!$G:$G=1)"),"#REF!") -> #REF! | E2: {=if($B$2:$B952 <> "", hyperlink("https://drive.google.com/drive/search?q=parent:" & Properties!$C$8 & "%20" & char(34) & $F$2:$F952 & char(34), "➔"), "")} -> #REF! | F2: {=if($B$2:$B952<>"","SP-"&$A$2:$A952 &"-"&$B$2:$B952&".pdf", "")} -> #REF!
A3: 001 | B3: Tortorich | C3: 002 | D3: Frank Tortorich, Jr., The Opening of the Carson River Route, 18 Overland Journal 1, 22 (Spring 2000) | E3: ➔ | F3: SP-001-Tortorich.pdf | G3: ME | H3: Y | I3: N/A | J3: Y | K3: None | L3: Stanford Searchworks | M3: N/A
A4: 002 | B4: Munson | C4: 002 | D4: Jeff Munson, “Emigrant Trail tour promises spectacular colors,” Tahoe Daily Tribune (Oct. 12, 2005), https://www.tahoedailytribune.com/news/emigrant-trail-tour-promises-spectacular-colors/ | E4: ➔ | F4: SP-002-Munson.pdf | G4: ME | H4: Y | I4: N/A | J4: N/A | K4: None | L4: Website | M4: N/A
A5: 003 | B5: Hope Valley Recreation | C5: 003 | D5: https://www.fs.usda.gov/Internet/FSE_DOCUMENTS/stelprdb5294291.pdf. | E5: ➔ | F5: SP-003-Hope Valley Recreation.pdf | G5: ME | H5: N | N5: The URL in the foonote leads to a 404 error. I tried finding the winter recreation map separately, just via google search, and arrived at this page: https://www.fs.usda.gov/r04/humboldt-toiyabe/recreation/hope-valley-sno-parktrailhead. Unfortunately, clicking the "Click here for a map" button on that page also yields a 404 error. I think the map may no longer exist.
A6: 004 | B6: Memorandum | C6: 004 | D6: Memorandum of Opinion and Order, Friends of Hope Valley v. U.S. Forest Serv., No. 2:00-cv-01900-DFL-KJM, 2 (E.D. Cal. Sept. 30, 2004) | E6: ➔ | F6: SP-004-Memorandum.pdf | G6: ME | H6: Y | I6: N/A | J6: N/A | K6: Yes: aff’d in part, dismissed in part, Friends of Hope Valley v. U.S. Forest Serv., 203 F. App'x 883 (9th Cir. 2006). | L6: Bloomberg (not available on Westlaw or Lexis) | M6: N/A | N6: I didn't merge the subsequent history into this sourcepull pdf, because we already have the 9th Circuit case as a separate source ID.
A7: 005 | B7: Friends of Hope Valley v US Forest Service | C7: 006 | D7: Friends of Hope Valley v. U.S. Forest Service, 203 Fed. Appx. 883 (9th Cir. 2006) (unpublished) | E7: ➔ | F7: SP-005-Friends of Hope Valley v US Forest Service.pdf | G7: ME | H7: Y | I7: N/A | J7: N/A | K7: None | L7: Westlaw | M7: N/A
A8: 006 | B8: APA | C8: 007 | D8: 5 U.S.C. §§ 551-553, 701-706 | E8: ➔ | F8: SP-006-APA.pdf | G8: ME | H8: Y | I8: N/A | J8: N/A | K8: None | L8: GPO | M8: N/A | N8: The sourcepull PDF includes §§ 551-553 and 701-706, in accordance with the author's footnote.
A9: 007 | B9: Infra Notes 113, 151-153 | C9: 007 | D9: infra notes 113, 151-153 | E9: ➔ | F9: SP-007-Infra Notes 113, 151-153.pdf | G9: ME | H9: Y | I9: N/A | J9: N/A | K9: None | L9: Internal Cross Ref | M9: N/A
A10: 008 | B10: Alsea Valley Alliance v Dep't of Commerce | C10: 008 | D10: Alsea Valley Alliance v. Dep’t of Commerce, 358 F.3d 1181, 1184 (9th Cir. 2004) | E10: ➔ | F10: SP-008-Alsea Valley Alliance v Dep't of Commerce.pdf | G10: ME | H10: Y | I10: N/A | J10: N/A | K10: None | L10: Westlaw | M10: N/A
A11: 009 | B11: Infra Part IB | C11: 009 | D11: infra Part I.B | E11: ➔ | F11: SP-009-Infra Part IB.pdf | G11: ME | H11: Y | I11: N/A | J11: N/A | K11: None | L11: Internal Cross Ref | M11: N/A
A12: 010 | B12: Infra Note 23 | C12: 009 | D12: infra note 23 | E12: ➔ | F12: SP-010-Infra Note 23.pdf | G12: ME | H12: Y | I12: N/A | J12: N/A | K12: None | L12: Internal Cross Ref | M12: N/A
A13: 011 | B13: Denver Cnty | C13: 010 | D13: C.W. by and through B.W. v. Denver Cnty. Sch. Dist. No. 1, 994 F.3d 1215, 1220 n.2 (10th Cir. 2021) | E13: ➔ | F13: SP-011-Denver Cnty.pdf | G13: ME | H13: Y | I13: N/A | J13: N/A | K13: None | L13: Westlaw | M13: N/A
A14: 012 | B14: Montana Env't Info CTR | C14: 010 | D14: Montana Env’t Info. Ctr. v. Haaland, No. 22-36002, 2023 WL 8166779, at *1 (9th Cir. Nov. 24, 2023) | E14: ➔ | F14: SP-012-Montana Env't Info CTR.pdf | G14: ME | H14: Y | I14: N/A | J14: N/A | K14: None | L14: Westlaw | M14: N/A
A15: 013 | B15: Dcor | C15: 010 | D15: DCOR, LLC v. U.S. Dep’t of the Interior, No. 3:21-CV-00120-N, 2023 WL 8628322, at *1 (N.D. Tex. Dec. 13, 2023) | E15: ➔ | F15: SP-013-Dcor.pdf | G15: ME | H15: Y | I15: N/A | J15: N/A | K15: None | L15: Westlaw | M15: N/A
A16: 014 | B16: Infra Part I | C16: 011 | D16: Part I, infra | E16: ➔ | F16: SP-014-Infra Part I.pdf | G16: ME | H16: Y | I16: N/A | J16: N/A | K16: None | L16: Internal Cross Ref | M16: N/A
A17: 015 | B17: Michaels | C17: 001 | D17: Jon D. Michaels, Constitutional Coup: Privatization’s Threat to the American Republic, 21-77 (2017) | E17: ➔ | F17: SP-015-Michaels.pdf | G17: ME | H17: Y | I17: Y (included both p.21-77 and 143-220; the latter range is cited in FN 200) | J17: N/A | K17: None | L17: Stanford Searchworks (full format-preserving ebook was available) | M17: N/A
A18: 016 | B18: Developments | C18: 011 | D18: Developments in the Law—Presidential Authority, V. Executive Appointments, 125 Harv. L. Rev. 2135, 2138 (2012) | E18: ➔ | F18: SP-016-Developments.pdf | G18: ME | H18: Y | I18: N/A | J18: Y | K18: None | L18: HeinOnline | M18: N/A
A19: 017 | B19: Ho | C19: 011 | D19: Daniel E. Ho & Erica L. Ross, Did Liberal Justices Invent the Standing Doctrine? An Empirical Study of the Evolution of Standing, 1921-2006, 62 Stan. L. Rev. 591, 647 & n.231 (2010) | E19: ➔ | F19: SP-017-Ho.pdf | G19: ME | H19: Y | I19: N/A | J19: Y | K19: None | L19: HeinOnline | M19: N/A
A20: 018 | B20: Jordan | C20: 011 | D20: William S. Jordan, III, Judges, Ideology, and Policy in the Administrative State: Lessons from A Decade of Hard Look Remands of EPA Rules, 53 Admin. L. Rev. 45, 46 (2001) | E20: ➔ | F20: SP-018-Jordan.pdf | G20: ME | H20: Y | I20: N/A | J20: Y | K20: None | L20: HeinOnline | M20: N/A
A21: 019 | B21: Finkelstein | C21: 012 | D21: Sullivan v. Finkelstein, 496 U.S. 617, 625 (1990) | E21: ➔ | F21: SP-019-Finkelstein.pdf | G21: ME | H21: Y | I21: N/A | J21: N/A | K21: None | L21: HeinOnline | M21: N/A
A22: 020 | B22: Infra Notes 89-97 and Accompanying Text Pp 17-19 | C22: 012 | D22: infra notes 89-97 and accompanying text pp. 17-19 | E22: ➔ | F22: SP-020-Infra Notes 89-97 and Accompanying Text Pp 17-19.pdf | G22: ME | H22: Y | I22: N/A | J22: N/A | K22: None | L22: Internal Cross Ref | M22: N/A | N22: I kept p.19 in the PDF because the author includes that page in the cross-reference, even though footnote 97 ends on p.18.
A23: 021 | B23: Lammon Appealability | C23: 013 | D23: Bryan Lammon, Finality, Appealability, and the Scope of Interlocutory Review, 93 Wash. L. Rev. 1809, 1834-37 (2018) | E23: ➔ | F23: SP-021-Lammon Appealability.pdf | G23: ME | H23: Y | I23: N/A | J23: Y | K23: None | L23: HeinOnline | M23: N/A
A24: 022 | B24: Lammon Dizzying | C24: 013 | D24: Bryan Lammon, Dizzying Gillespie: The Exaggerated Death of the Balancing Approach and the Inescapable Allure of Flexibility in Appellate Jurisdiction, 51 U. Rich. L. Rev. 371, 386-93 (2017) | E24: ➔ | F24: SP-022-Lammon Dizzying.pdf | G24: ME | H24: Y | I24: N/A | J24: Y | K24: None | L24: HeinOnline | M24: N/A
A25: 023 | B25: Krent | C25: 013 | D25: Harold J. Krent, Situating Structural Challenges to Agency Authority Within the Framework of the Finality Principle, 98 Ind. L.J. Supplement 1, 10 n.73 (2023) | E25: ➔ | F25: SP-023-Krent.pdf | G25: ME | H25: Y | I25: N/A | J25: Y | K25: None | L25: Indiana Law Journal Website (unavailable elsewhere) | M25: N/A | N25: This source is from the Indiana Law Journal "Supplement," which is Indaina's online law journal. No table of contents was available, so I included some additional screenshots/information in the sourcepull pdf to show consecutive pagination and provide the necessary citation information.
A26: 024 | B26: Biever | C26: 013 | D26: Jennifer L. Biever & Ana Maria Gutierrez, The Uncertain Question of Remedies Should a Challenge Prevail, 2016 NO. 5 RMMLF-INST PAPER NO. 13, 28-29 (2016) | E26: ➔ | F26: SP-024-Biever.pdf | G26: ME | H26: Y | I26: N/A | J26: No | K26: None | L26: Westlaw | M26: N/A | N26: This appears to be a paper that was presented at a conference; all of the papers presented at the conference were subsequently published in a volume that is available for purchase here: https://www.fnrel.org/publications/bookstore/challenging-and-defending-federal-natural-resource-agency-decisions. As far as I can tell, Stanford libraries do not have that volume. The paper is also available on Westlaw, which is presumably where the author found it. I pulled the Westlaw version, but I'm happy to try something else.
A27: 025 | B27: Lynch | C27: 013 | D27: Michele D. Lynch, Remands Are A Consequence of Administrative Law, So Why Are We All So Frustrated?, 23 Tul. J. Int’l & Comp. L. 383, 392 (2015) | E27: ➔ | F27: SP-025-Lynch.pdf | G27: ME | H27: Y | I27: N/A | J27: Y | K27: None | L27: HeinOnline | M27: N/A
A28: 026 | B28: Federal Practice 3914 32 | C28: 013 | D28: Federal Practice & Procedure, § 3914.32 Orders Prior to Trial—Administrative Review, 15B Fed. Prac. & Proc. Juris. § 3914.32 (2d ed. June 2024 Update) | E28: ➔ | F28: SP-026-Federal Practice 3914 32.pdf | G28: ME | H28: Y | I28: N/A | J28: N/A | K28: None | L28: Westlaw | M28: N/A | N28: Per RB 15.4, I pulled the online (Westlaw) version of this treatise, because it is regularly updated.
A29: 027 | B29: Federal Practice 3903 | C29: 013 | D29: Federal Practice & Procedure, § 3903 Pragmatic Finality, 15A Fed. Prac. & Proc. Juris. § 3913 (3d ed. June 2024 Update) | E29: ➔ | F29: SP-027-Federal Practice 3903.pdf | G29: ME | H29: Y | I29: N/A | J29: N/A | K29: None | L29: Westlaw | M29: N/A | N29: Same comment as previous row.
A30: 028 | B30: 73a CJS | C30: 013 | D30: 73A C.J.S. Pub. Admin. Law & Proc. § 561 (May 2024) | E30: ➔ | F30: SP-028-73a CJS.pdf | G30: ME | H30: Y | I30: N/A | J30: N/A | K30: None | L30: Westlaw | M30: N/A | N30: Same comment as previous row.
A31: 029 | B31: Fed Ct | C31: 013 | D31: Fed. Ct. App. Manual § 2:3 (7th ed. May 2024) | E31: ➔ | F31: SP-029-Fed Ct.pdf | G31: ME | H31: Y | I31: N/A | J31: N/A | K31: None | L31: Westlaw | M31: N/A | N31: Same comment as previous row.
A32: 030 | B32: Infra Notes 39-51 and Accompanying Text | C32: 014 | D32: infra notes 39-51 and accompanying text | E32: ➔ | F32: SP-030-Infra Notes 39-51 and Accompanying Text.pdf | G32: ME | H32: Y | I32: N/A | J32: N/A | K32: None | L32: Internal Cross Ref | M32: N/A
A33: 031 | B33: Infra Notes 46-48 and Accompanying Text | C33: 015 | D33: infra notes 46-48 and accompanying text | E33: ➔ | F33: SP-031-Infra Notes 46-48 and Accompanying Text.pdf | G33: ME | H33: Y | I33: N/A | J33: N/A | K33: None | L33: Internal Cross Ref | M33: N/A
A34: 032 | B34: Pueblo of Sandia v Babbitt | C34: 016 | D34: Pueblo of Sandia v. Babbitt, 231 F.3d 878, 880 (D.C. Cir. 2000) | E34: ➔ | F34: SP-032-Pueblo of Sandia v Babbitt.pdf | G34: ME | H34: Y | I34: N/A | J34: N/A | K34: None | L34: Westlaw | M34: N/A
A35: 033 | B35: CTR for Biological Diversity v Bureau of Land MGMT | C35: 017 | D35: Ctr. for Biological Diversity v. Bureau of Land Mgmt., 69 F.4th 588, 597-98 (9th Cir. 2023) (Friedland and Bennett, JJ., concurring) | E35: ➔ | F35: SP-033-CTR for Biological Diversity v Bureau of Land MGMT.pdf | G35: ME | H35: Y | I35: N/A | J35: N/A | K35: None | L35: Westlaw | M35: N/A
A36: 034 | B36: NY Legal Assistance GRP v Cardona | C36: 017 | D36: N.Y. Legal Assistance Grp. v. Cardona, No. 21-888-CV, 2024 WL 64220, at *3-4 (2d Cir. Jan. 5, 2024) | E36: ➔ | F36: SP-034-NY Legal Assistance GRP v Cardona.pdf | G36: ME | H36: Y | I36: N/A | J36: N/A | K36: None | L36: Westlaw | M36: N/A
A37: 035 | B37: Infra Notes 132-192 and Accompanying Text | C37: 018 | D37: infra notes 132-192 and accompanying text | E37: ➔ | F37: SP-035-Infra Notes 132-192 and Accompanying Text.pdf | G37: ME | H37: Y | I37: N/A | J37: N/A | K37: None | L37: Internal Cross Ref | M37: N/A
A38: 036 | B38: Infra Notes 193-194 | C38: 019 | D38: infra notes 193-194, 262-270 and accompanying text | E38: ➔ | F38: SP-036-Infra Notes 193-194.pdf | G38: ME | H38: Y | I38: N/A | J38: N/A | K38: None | L38: Internal Cross Ref | M38: N/A | N38: Flagging that this cross reference refers to two ranges of footnotes, which is not reflected in the source ID name.
A39: 037 | B39: Clopton | C39: 020 | D39: Zachary D. Clopton & Katherine Shaw, Public Law Litigation and Electoral Time, 2023 Wis. L. Rev. 1513, 1521–22 (2023) | E39: ➔ | F39: SP-037-Clopton.pdf | G39: ME | H39: Y | I39: N/A | J39: Y | K39: None | L39: HeinOnline | M39: N/A
A40: 038 | B40: Jackson | C40: 021 | D40: Jackson v. Bd. of Civ. Serv. Comm’rs of City of Los Angeles, 99 Cal. App. 5th 648, 655-62, 318 Cal. Rptr. 3d 79 (2024) | E40: ➔ | F40: SP-038-Jackson.pdf | G40: ME | H40: Y | I40: N/A | J40: N/A | K40: None | L40: Westlaw | M40: N/A
...

Sheet CC (nn. 1-37); LJ
A1: Source | F1: Drive | I1: Round 1 | Q1: Round 2
A2: Short Name | B2: ID | C2: SP String (DNE) | D2: R1 String (DNE) | E2: R2 String (DNE) | F2: SP | G2: R1 | H2: R2 | I2: MEM | J2: Fn# | K2: Cite# | L2: Supports? | M2: Citation Elements | N2: MEM Comments | O2: SE Response | P2: Kickback Response | Q2: MEM | R2: Fn# | S2: Cite# | T2: Supports? | U2: Citation Elements | V2: MEM Comments | W2: SE Response | X2: Kickback Response
A3: Keep this row hidden / do not edit! | B3: {=IF($A$3:$A88<>"", XLOOKUP($A$3:$A88, Sourcepull!$B$3:$B88, Sourcepull!$A$3:$A88, ""), "")} | C3: {=if($A$3:$A88<>"","SP-"&$B$3:$B88&"-"&$A$3:$A88&".pdf", "")} -> SP--Keep this row hidden / do not edit!.pdf | D3: {=if($J$3:$J88<>"","R1-"&$J$3:$J88&"-"&$K$3:$K88&"-"&$B$3:$B88&"-"&$A$3:$A88&".pdf", "")} | E3: {=if($R$3:$R88<>"","R2-"&$R$3:$R88&"-"&$S$3:$S88&"-"&$B$3:$B88&"-"&$A$3:$A88&".pdf", "")} | F3: {=if($C$3:$C88 <> "", hyperlink("https://drive.google.com/drive/search?q=parent:" & Properties!$C$8 & "%20" & char(34) & $C$3:$C88 & char(34), "➔"), "")} -> ➔ | G3: {=if($D$3:$D88 <> "", hyperlink("https://drive.google.com/drive/search?q=parent:" & Properties!$C$9 & "%20" & char(34) & $D$3:$D88 & char(34), "➔"), "")} | H3: {=if($E$3:$E88 <> "", hyperlink("https://drive.google.com/drive/search?q=parent:" & Properties!$C$10 & "%20" & char(34) & $E$3:$E88 & char(34), "➔"), "")}
A4: Herman | B4: 328 | C4: SP-328-Herman.pdf | D4: R1-001-01-328-Herman.pdf | F4: ➔ | G4: ➔ | I4: LJ | J4: 001 | K4: 01
A5: Cudahy | B5: 329 | C5: SP-329-Cudahy.pdf | D5: R1-001-02-329-Cudahy.pdf | F5: ➔ | G5: ➔ | I5: LJ | J5: 001 | K5: 02
A6: Carson | B6: 330 | C6: SP-330-Carson.pdf | D6: R1-001-03-330-Carson.pdf | F6: ➔ | G6: ➔ | I6: LJ | J6: 001 | K6: 03
A7: Washoe USDA | B7: 331 | C7: SP-331-Washoe USDA.pdf | D7: R1-001-04-331-Washoe USDA.pdf | F7: ➔ | G7: ➔ | I7: LJ | J7: 001 | K7: 04
A8: Washoe History | B8: 332 | C8: SP-332-Washoe History.pdf | D8: R1-001-05-332-Washoe History.pdf | F8: ➔ | G8: ➔ | I8: LJ | J8: 001 | K8: 05
A9: Tortorich | B9: 001 | C9: SP-001-Tortorich.pdf | D9: R1-002-01-001-Tortorich.pdf | F9: ➔ | G9: ➔ | I9: LJ | J9: 002 | K9: 01
A10: Munson | B10: 002 | C10: SP-002-Munson.pdf | D10: R1-002-02-002-Munson.pdf | F10: ➔ | G10: ➔ | I10: LJ | J10: 002 | K10: 02
A11: Hope Valley Recreation | B11: 003 | C11: SP-003-Hope Valley Recreation.pdf | D11: R1-003-01-003-Hope Valley Recreation.pdf | F11: ➔ | G11: ➔ | I11: LJ | J11: 003 | K11: 01
A12: Memorandum | B12: 004 | C12: SP-004-Memorandum.pdf | D12: R1-004-01-004-Memorandum.pdf | F12: ➔ | G12: ➔ | I12: LJ | J12: 004 | K12: 01
A13: Memorandum | B13: 004 | C13: SP-004-Memorandum.pdf | D13: R1-005-01-004-Memorandum.pdf | F13: ➔ | G13: ➔ | I13: LJ | J13: 005 | K13: 01
A14: Friends of Hope Valley v US Forest Service | B14: 005 | C14: SP-005-Friends of Hope Valley v US Forest Service.pdf | D14: R1-006-01-005-Friends of Hope Valley v US Forest Service.pdf | F14: ➔ | G14: ➔ | I14: LJ | J14: 006 | K14: 01
A15: Friends of Hope Valley v US Forest Service | B15: 005 | C15: SP-005-Friends of Hope Valley v US Forest Service.pdf | D15: R1-007-01-005-Friends of Hope Valley v US Forest Service.pdf | F15: ➔ | G15: ➔ | I15: LJ | J15: 007 | K15: 01
... A56: Infra Notes 29 | B56: 044 | C56: SP-044-Infra Notes 29.pdf | D56: R1-023-01-044-Infra Notes 29.pdf | F56: ➔ | G56: ➔ | I56: LJ | J56: 023 | K56: 01
A57: 1291 | B57: 045 | C57: SP-045-1291.pdf | D57: R1-024-01-045-1291.pdf | F57: ➔ | G57: ➔ | I57: LJ | J57: 024 | K57: 01
A58: 1292 | B58: 046 | C58: SP-046-1292.pdf | D58: R1-025-01-046-1292.pdf | F58: ➔ | G58: ➔ | I58: LJ | J58: 025 | K58: 01
A59: Federal Rule | B59: 047 | C59: SP-047-Federal Rule.pdf | D59: R1-026-01-047-Federal Rule.pdf | F59: ➔ | G59: ➔ | I59: LJ | J59: 026 | K59: 01
A60: 1292 | B60: 046 | C60: SP-046-1292.pdf | D60: R1-026-02-046-1292.pdf | F60: ➔ | G60: ➔ | I60: LJ | J60: 026 | K60: 02
A61: Infra Notes 280 | B61: 048 | C61: SP-048-Infra Notes 280.pdf | D61: R1-026-03-048-Infra Notes 280.pdf | F61: ➔ | G61: ➔ | I61: LJ | J61: 026 | K61: 03
A62: Collord v US Dep't of the Interior | B62: 049 | C62: SP-049-Collord v US Dep't of the Interior.pdf | D62: R1-027-01-049-Collord v US Dep't of the Interior.pdf | F62: ➔ | G62: ➔ | I62: LJ | J62: 027 | K62: 01
A63: Infra Notes 132-181 | B63: 050 | C63: SP-050-Infra Notes 132-181.pdf | D63: R1-027-02-050-Infra Notes 132-181.pdf | F63: ➔ | G63: ➔ | I63: LJ | J63: 027 | K63: 02
A64: Alsea Valley Alliance v Dep't of Commerce | B64: 008 | C64: SP-008-Alsea Valley Alliance v Dep't of Commerce.pdf | D64: R1-028-01-008-Alsea Valley Alliance v Dep't of Commerce.pdf | F64: ➔ | G64: ➔ | I64: LJ | J64: 028 | K64: 01
A65: Crowder v Sullivan | B65: 051 | C65: SP-051-Crowder v Sullivan.pdf | D65: R1-028-02-051-Crowder v Sullivan.pdf | F65: ➔ | G65: ➔ | I65: LJ | J65: 028 | K65: 02
A66: Federal Practice 3914 32 | B66: 026 | C66: SP-026-Federal Practice 3914 32.pdf | D66: R1-028-03-026-Federal Practice 3914 32.pdf | F66: ➔ | G66: ➔ | I66: LJ | J66: 028 | K66: 03
A67: Papotto | B67: 052 | C67: SP-052-Papotto.pdf | D67: R1-029-01-052-Papotto.pdf | F67: ➔ | G67: ➔ | I67: LJ | J67: 029 | K67: 01
A68: Kreider | B68: 053 | C68: SP-053-Kreider.pdf | D68: R1-029-02-053-Kreider.pdf | F68: ➔ | G68: ➔ | I68: LJ | J68: 029 | K68: 02
A69: Digital Equip Corp | B69: 054 | C69: SP-054-Digital Equip Corp.pdf | D69: R1-029-03-054-Digital Equip Corp.pdf | F69: ➔ | G69: ➔ | I69: LJ | J69: 029 | K69: 03
A70: Bagley | B70: 055 | C70: SP-055-Bagley.pdf | D70: R1-030-01-055-Bagley.pdf | F70: ➔ | G70: ➔ | I70: LJ | J70: 030 | K70: 01
A71: 706 | B71: 056 | C71: SP-056-706.pdf | D71: R1-030-02-056-706.pdf | F71: ➔ | G71: ➔ | I71: LJ | J71: 030 | K71: 02
A72: Chenery Corp | B72: 057 | C72: SP-057-Chenery Corp.pdf | D72: R1-031-01-057-Chenery Corp.pdf | F72: ➔ | G72: ➔ | I72: LJ | J72: 031 | K72: 01
A73: Wages and White Lion Invs | B73: 058 | C73: SP-058-Wages and White Lion Invs.pdf | D73: R1-031-02-058-Wages and White Lion Invs.pdf | F73: ➔ | G73: ➔ | I73: LJ | J73: 031 | K73: 02
A74: Glicksman | B74: 059 | C74: SP-059-Glicksman.pdf | D74: R1-031-03-059-Glicksman.pdf | F74: ➔ | G74: ➔ | I74: LJ | J74: 031 | K74: 03
A75: Walker Referral | B75: 060 | C75: SP-060-Walker Referral.pdf | D75: R1-031-04-060-Walker Referral.pdf | F75: ➔ | G75: ➔ | I75: LJ | J75: 031 | K75: 04
A76: Walker Ordinary | B76: 061 | C76: SP-061-Walker Ordinary.pdf | D76: R1-031-05-061-Walker Ordinary.pdf | F76: ➔ | G76: ➔ | I76: LJ | J76: 031 | K76: 05
A77: Infra Notes 257-261 and Accompanying Text | B77: 062 | C77: SP-062-Infra Notes 257-261 and Accompanying Text.pdf | D77: R1-032-01-062-Infra Notes 257-261 and Accompanying Text.pdf | F77: ➔ | G77: ➔ | I77: LJ | J77: 032 | K77: 01
A78: Revesz | B78: 063 | C78: SP-063-Revesz.pdf | D78: R1-033-01-063-Revesz.pdf | F78: ➔ | G78: ➔ | I78: LJ | J78: 033 | K78: 01
A79: Fine | B79: 064 | C79: SP-064-Fine.pdf | D79: R1-033-02-064-Fine.pdf | F79: ➔ | G79: ➔ | I79: LJ | J79: 033 | K79: 02
A80: Motor Vehicle Mfrs | B80: 065 | C80: SP-065-Motor Vehicle Mfrs.pdf | D80: R1-034-01-065-Motor Vehicle Mfrs.pdf | F80: ➔ | G80: ➔ | I80: LJ | J80: 034 | K80: 01
...

Sheet Copy of CC
A1: Source | F1: Drive | I1: Round 1 | Q1: Round 2
A2: Short Name | B2: ID | C2: SP String (DNE) | D2: R1 String (DNE) | E2: R2 String (DNE) | F2: SP | G2: R1 | H2: R2 | I2: MEM | J2: Fn# | K2: Cite# | L2: Supports? | M2: Citation Elements | N2: MEM Comments | O2: SE Response | P2: Kickback Response | Q2: MEM | R2: Fn# | S2: Cite# | T2: Supports? | U2: Citation Elements | V2: MEM Comments | W2: SE Response | X2: Kickback Response
A3: Keep this row hidden / do not edit! | B3: {=IF($A$3:$A11<>"", XLOOKUP($A$3:$A11, Sourcepull!$B$3:$B11, Sourcepull!$A$3:$A11, ""), "")} | C3: {=if($A$3:$A11<>"","SP-"&$B$3:$B11&"-"&$A$3:$A11&".pdf", "")} -> SP--Keep this row hidden / do not edit!.pdf | D3: {=if($J$3:$J11<>"","R1-"&$J$3:$J11&"-"&$K$3:$K11&"-"&$B$3:$B11&"-"&$A$3:$A11&".pdf", "")} | E3: {=if($R$3:$R11<>"","R2-"&$R$3:$R11&"-"&$S$3:$S11&"-"&$B$3:$B11&"-"&$A$3:$A11&".pdf", "")} | F3: {=if($C$3:$C11 <> "", hyperlink("https://drive.google.com/drive/search?q=parent:" & Properties!$C$8 & "%20" & char(34) & $C$3:$C11 & char(34), "➔"), "")} -> ➔ | G3: {=if($D$3:$D11 <> "", hyperlink("https://drive.google.com/drive/search?q=parent:" & Properties!$C$9 & "%20" & char(34) & $D$3:$D11 & char(34), "➔"), "")} | H3: {=if($E$3:$E11 <> "", hyperlink("https://drive.google.com/drive/search?q=parent:" & Properties!$C$10 & "%20" & char(34) & $E$3:$E11 & char(34), "➔"), "")}

Sheet CC (nn. 38-81); SSH
A1: Source | F1: Drive | I1: Round 1 | Q1: Round 2
A2: Short Name | B2: ID | C2: SP String (DNE) | D2: R1 String (DNE) | E2: R2 String (DNE) | F2: SP | G2: R1 | H2: R2 | I2: MEM | J2: Fn# | K2: Cite# | L2: Supports? | M2: Citation Elements | N2: MEM Comments | O2: SE Response | P2: Kickback Response | Q2: MEM | R2: Fn# | S2: Cite# | T2: Supports? | U2: Citation Elements | V2: MEM Comments | W2: SE Response | X2: Kickback Response
A3: Keep this row hidden / do not edit! | B3: {=IF($A$3:$A82<>"", XLOOKUP($A$3:$A82, Sourcepull!$B$3:$B82, Sourcepull!$A$3:$A82, ""), "")} | C3: {=if($A$3:$A82<>"","SP-"&$B$3:$B82&"-"&$A$3:$A82&".pdf", "")} -> SP--Keep this row hidden / do not edit!.pdf | D3: {=if($J$3:$J82<>"","R1-"&$J$3:$J82&"-"&$K$3:$K82&"-"&$B$3:$B82&"-"&$A$3:$A82&".pdf", "")} | E3: {=if($R$3:$R82<>"","R2-"&$R$3:$R82&"-"&$S$3:$S82&"-"&$B$3:$B82&"-"&$A$3:$A82&".pdf", "")} | F3: {=if($C$3:$C82 <> "", hyperlink("https://drive.google.com/drive/search?q=parent:" & Properties!$C$8 & "%20" & char(34) & $C$3:$C82 & char(34), "➔"), "")} -> ➔ | G3: {=if($D$3:$D82 <> "", hyperlink("https://drive.google.com/drive/search?q=parent:" & Properties!$C$9 & "%20" & char(34) & $D$3:$D82 & char(34), "➔"), "")} | H3: {=if($E$3:$E82 <> "", hyperlink("https://drive.google.com/drive/search?q=parent:" & Properties!$C$10 & "%20" & char(34) & $E$3:$E82 & char(34), "➔"), "")}
A4: Vista | B4: 069 | C4: SP-069-Vista.pdf | D4: R1-038-01-069-Vista.pdf | F4: ➔ | G4: ➔ | I4: SSH | J4: 038 | K4: 01
A5: Act of Sept 24 | B5: 070 | C5: SP-070-Act of Sept 24.pdf | D5: R1-039-01-070-Act of Sept 24.pdf | F5: ➔ | G5: ➔ | I5: SSH | J5: 039 | K5: 01
A6: Federal Practice 3906 | B6: 071 | C6: SP-071-Federal Practice 3906.pdf | D6: R1-040-01-071-Federal Practice 3906.pdf | F6: ➔ | G6: ➔ | I6: SSH | J6: 040 | K6: 01
A7: Metcalfe | B7: 072 | C7: SP-072-Metcalfe.pdf | D7: R1-040-02-072-Metcalfe.pdf | F7: ➔ | G7: ➔ | I7: SSH | J7: 040 | K7: 02
A8: Catlin v United States | B8: 073 | C8: SP-073-Catlin v United States.pdf | D8: R1-041-01-073-Catlin v United States.pdf | F8: ➔ | G8: ➔ | I8: SSH | J8: 041 | K8: 01
A9: 1291 | B9: 045 | C9: SP-045-1291.pdf | D9: R1-042-01-045-1291.pdf | F9: ➔ | G9: ➔ | I9: SSH | J9: 042 | K9: 01
A10: 62 Stat | B10: 074 | C10: SP-074-62 Stat.pdf | D10: R1-042-02-074-62 Stat.pdf | F10: ➔ | G10: ➔ | I10: SSH | J10: 042 | K10: 02
A11: Bachowski v Usery | B11: 075 | C11: SP-075-Bachowski v Usery.pdf | D11: R1-043-01-075-Bachowski v Usery.pdf | F11: ➔ | G11: ➔ | I11: SSH | J11: 043 | K11: 01
A12: Katz v Carte Blanche Corp | B12: 076 | C12: SP-076-Katz v Carte Blanche Corp.pdf | D12: R1-043-02-076-Katz v Carte Blanche Corp.pdf | F12: ➔ | G12: ➔ | I12: SSH | J12: 043 | K12: 02
A13: 1292 | B13: 046 | C13: SP-046-1292.pdf | D13: R1-043-03-046-1292.pdf | F13: ➔ | G13: ➔ | I13: SSH | J13: 043 | K13: 03
